<?xml version="1.0" encoding="utf-8"?>
<!-- This URDF was automatically created by SolidWorks to URDF Exporter! Originally created by Stephen Brawner (brawner@gmail.com) 
     Commit Version: 1.6.0-4-g7f85cfe  Build Version: 1.6.7995.38578
     For more information, please see http://wiki.ros.org/sw_urdf_exporter -->
<robot
  name="FR5">
  <link
    name="base_link">
    <inertial>
      <origin
        xyz="-0.000318956334379786 0.0424634278853759 0.000296731941359847"
        rpy="0 0 0" />
      <mass
        value="0.599445534393006" />
      <inertia
        ixx="0.00114206030442934"
        ixy="-7.15379469999523E-06"
        ixz="-5.68649059708126E-06"
        iyy="0.00167440728779363"
        iyz="6.63620502605694E-06"
        izz="0.00114168272876612" />
    </inertial>
    <visual>
      <origin
        xyz="0 0 0"
        rpy="0 0 0" />
      <geometry>
        <mesh
          filename="package://FR5/meshes/base_link.STL" />
      </geometry>
      <material
        name="">
        <color
          rgba="1 1 1 1" />
      </material>
    </visual>
    <collision>
      <origin
        xyz="0 0 0"
        rpy="0 0 0" />
      <geometry>
        <mesh
          filename="package://FR5/meshes/base_link.STL" />
      </geometry>
    </collision>
  </link>
  <link
    name="Link_1">
    <inertial>
      <origin
        xyz="3.14248391854288E-07 0.0722971481745178 0.00409704327529289"
        rpy="0 0 0" />
      <mass
        value="1.62144524319144" />
      <inertia
        ixx="0.0039730540694634"
        ixy="-2.35159393739738E-08"
        ixz="-8.26544630738003E-10"
        iyy="0.0030289160958611"
        iyz="-4.772687273196E-05"
        izz="0.00385357913706097" />
    </inertial>
    <visual>
      <origin
        xyz="0 0 0"
        rpy="0 0 0" />
      <geometry>
        <mesh
          filename="package://FR5/meshes/Link_1.STL" />
      </geometry>
      <material
        name="">
        <color
          rgba="1 1 1 1" />
      </material>
    </visual>
    <collision>
      <origin
        xyz="0 0 0"
        rpy="0 0 0" />
      <geometry>
        <mesh
          filename="package://FR5/meshes/Link_1.STL" />
      </geometry>
    </collision>
  </link>
  <joint
    name="J1"
    type="continuous">
    <origin
      xyz="0 0 0.073995"
      rpy="1.5708 0 0" />
    <parent
      link="base_link" />
    <child
      link="Link_1" />
    <axis
      xyz="0 1 0" />
  </joint>
  <link
    name="Link_2">
    <inertial>
      <origin
        xyz="-0.212499308599412 6.44395092906764E-08 0.0746126182262269"
        rpy="0 0 0" />
      <mass
        value="5.35553310056889" />
      <inertia
        ixx="0.0105141689185762"
        ixy="8.47394157036307E-07"
        ixz="-7.13377002825584E-07"
        iyy="0.168845342797303"
        iyz="-1.33055343819621E-07"
        izz="0.166564407800873" />
    </inertial>
    <visual>
      <origin
        xyz="0 0 0"
        rpy="0 0 0" />
      <geometry>
        <mesh
          filename="package://FR5/meshes/Link_2.STL" />
      </geometry>
      <material
        name="">
        <color
          rgba="1 0.545098039215686 0 1" />
      </material>
    </visual>
    <collision>
      <origin
        xyz="0 0 0"
        rpy="0 0 0" />
      <geometry>
        <mesh
          filename="package://FR5/meshes/Link_2.STL" />
      </geometry>
    </collision>
  </link>
  <joint
    name="J2"
    type="continuous">
    <origin
      xyz="0 0.078005 0.059795"
      rpy="0 0 -1.5708" />
    <parent
      link="Link_1" />
    <child
      link="Link_2" />
    <axis
      xyz="0 0 1" />
  </joint>
  <link
    name="Link_3">
    <inertial>
      <origin
        xyz="-0.187988130249523 2.19699398000276E-06 -0.0531566052890365"
        rpy="0 0 0" />
      <mass
        value="2.84180149560993" />
      <inertia
        ixx="0.00315084273123314"
        ixy="3.99950246324936E-07"
        ixz="-0.00254083713110811"
        iyy="0.0628440670460744"
        iyz="1.48702916959308E-07"
        izz="0.0624112448720477" />
    </inertial>
    <visual>
      <origin
        xyz="0 0 0"
        rpy="0 0 0" />
      <geometry>
        <mesh
          filename="package://FR5/meshes/Link_3.STL" />
      </geometry>
      <material
        name="">
        <color
          rgba="1 1 1 1" />
      </material>
    </visual>
    <collision>
      <origin
        xyz="0 0 0"
        rpy="0 0 0" />
      <geometry>
        <mesh
          filename="package://FR5/meshes/Link_3.STL" />
      </geometry>
    </collision>
  </link>
  <joint
    name="J3"
    type="continuous">
    <origin
      xyz="-0.425 0 0"
      rpy="0 0 0" />
    <parent
      link="Link_2" />
    <child
      link="Link_3" />
    <axis
      xyz="0 0 1" />
  </joint>
  <link
    name="Link_4">
    <inertial>
      <origin
        xyz="2.5803535688984E-07 -0.00373781523290517 0.0370610606061226"
        rpy="0 0 0" />
      <mass
        value="0.602647151987744" />
      <inertia
        ixx="0.000799624094321744"
        ixy="5.56026667285951E-09"
        ixz="1.09853394336186E-08"
        iyy="0.000572240282383422"
        iyz="1.39810041027403E-05"
        izz="0.000736731215719506" />
    </inertial>
    <visual>
      <origin
        xyz="0 0 0"
        rpy="0 0 0" />
      <geometry>
        <mesh
          filename="package://FR5/meshes/Link_4.STL" />
      </geometry>
      <material
        name="">
        <color
          rgba="0.792156862745098 0.819607843137255 0.929411764705882 1" />
      </material>
    </visual>
    <collision>
      <origin
        xyz="0 0 0"
        rpy="0 0 0" />
      <geometry>
        <mesh
          filename="package://FR5/meshes/Link_4.STL" />
      </geometry>
    </collision>
  </link>
  <joint
    name="J4"
    type="continuous">
    <origin
      xyz="-0.39501 0 0"
      rpy="0 0 -1.5708" />
    <parent
      link="Link_3" />
    <child
      link="Link_4" />
    <axis
      xyz="0 0 1" />
  </joint>
  <link
    name="Link_5">
    <inertial>
      <origin
        xyz="-2.65792619447547E-07 -0.045058325607378 0.00384492672991213"
        rpy="0 0 0" />
      <mass
        value="0.585859255416681" />
      <inertia
        ixx="0.00076304073358568"
        ixy="1.13129395939287E-08"
        ixz="5.52165052112889E-09"
        iyy="0.000724546261667257"
        iyz="1.05849800870907E-05"
        izz="0.000536037719580454" />
    </inertial>
    <visual>
      <origin
        xyz="0 0 0"
        rpy="0 0 0" />
      <geometry>
        <mesh
          filename="package://FR5/meshes/Link_5.STL" />
      </geometry>
      <material
        name="">
        <color
          rgba="0.792156862745098 0.819607843137255 0.929411764705882 1" />
      </material>
    </visual>
    <collision>
      <origin
        xyz="0 0 0"
        rpy="0 0 0" />
      <geometry>
        <mesh
          filename="package://FR5/meshes/Link_5.STL" />
      </geometry>
    </collision>
  </link>
  <joint
    name="J5"
    type="continuous">
    <origin
      xyz="0 -0.057 0.042005"
      rpy="0 0 0" />
    <parent
      link="Link_4" />
    <child
      link="Link_5" />
    <axis
      xyz="0 1 0" />
  </joint>
  <link
    name="Empty_Link">
    <inertial>
      <origin
        xyz="-2.39745138341796E-05 0.0229219663437983 7.59525357927338E-05"
        rpy="0 0 0" />
      <mass
        value="0.194599495872035" />
      <inertia
        ixx="0.000102993340356853"
        ixy="9.4496112229953E-08"
        ixz="1.9030030540061E-07"
        iyy="0.00015409235874183"
        iyz="4.44557640516086E-09"
        izz="0.00010278076102126" />
    </inertial>
    <visual>
      <origin
        xyz="0 0 0"
        rpy="0 0 0" />
      <geometry>
        <mesh
          filename="package://FR5/meshes/Empty_Link.STL" />
      </geometry>
      <material
        name="">
        <color
          rgba="0.666666666666667 0.698039215686274 0.764705882352941 1" />
      </material>
    </visual>
    <collision>
      <origin
        xyz="0 0 0"
        rpy="0 0 0" />
      <geometry>
        <mesh
          filename="package://FR5/meshes/Empty_Link.STL" />
      </geometry>
    </collision>
  </link>
  <joint
    name="J6"
    type="continuous">
    <origin
      xyz="0 -0.0488 0.053"
      rpy="1.5708 0 2.0705" />
    <parent
      link="Link_5" />
    <child
      link="Empty_Link" />
    <axis
      xyz="0 1 0" />
  </joint>
</robot>